<sdf version='1.6'>
    <model name='HG_boat'>
        <link name='base_link'>
            <pose>0.000499 -0.009127 0.06786 0 0 0</pose>
            <inertial>
                <pose >0.000499 -0.009127 0.06786 0 0 0</pose>
                <mass>35</mass>
                <inertia>
                    <ixx>6.4640524405000015</ixx>
                    <ixy>0</ixy>
                    <ixz>0</ixz>
                    <iyy>4.5735524405</iyy>
                    <iyz>0</iyz>
                    <izz>9.9905</izz>
                </inertia>
            </inertial>
        
            <visual name='base_link'>
                <pose>0 0 0 0 0 0</pose>
                <geometry>
                <mesh>
                    <scale>0.001 0.001 0.001</scale>
                    <uri>model://HG_boat/meshes/Body_concept_no_float_no_cam_no_imu_v1.stl</uri>
                </mesh>
                </geometry>
            </visual>

            <collision name='base_link_collision'>
                <pose>0 0 0 0 0 0</pose>
                <geometry>
                    <mesh>
                        <scale>0.001 0.001 0.001</scale>
                        <uri>model://HG_boat/meshes/Body_concept_no_float_no_cam_no_imu_v1.stl</uri>
                    </mesh>
                </geometry>
            </collision>
            
        </link>

        <link name="floating1">
            <pose> 0.285 0 0.05 0 0 3.141592653589793</pose>
            <inertial>
                <pose>0 0 0 0 0 0</pose>
                <mass>5.615E+01</mass>
                <inertia>
                    <ixx>4.649</ixx>
                    <ixy>0</ixy>
                    <ixz>0</ixz>
                    <iyy>4.770e-01</iyy>
                    <iyz>0</iyz>
                    <izz>4.868</izz>
                </inertia>
            </inertial>

            <visual name='floating1'>
                <pose>0 0 0 0 0 0</pose>
                <geometry>
                <mesh>
                    <scale>0.001 0.001 0.001</scale>
                    <uri>model://HG_boat/meshes/Flotation_v1.stl</uri>
                </mesh>
                </geometry>
            </visual>

            <collision name='floating1_collision'>
                <pose>0 0 0 0 0 0</pose>
                <geometry>
                    <mesh>
                        <scale>0.001 0.001 0.001</scale>
                        <uri>model://HG_boat/meshes/Flotation_v1.stl</uri>
                    </mesh>
                </geometry>
            </collision>

        </link>

        <joint name="joint_floating1_body" type="revolute">
            <pose> 0 0 0 0 0 0</pose>
            <parent>base_link</parent>
            <child>floating1</child>
            <axis>
                <xyz>0 0 0</xyz>
                <limit>
                    <lower>0</lower>
                    <upper>0</upper>
                </limit>
                <dynamics>
                <!-- <damping>0.05</damping>
                <friction>0.05</friction> -->
                    <spring_reference>0</spring_reference>
                    <spring_stiffness>0</spring_stiffness>
                </dynamics>
                <use_parent_model_frame>1</use_parent_model_frame>
            </axis>
        </joint>

        <link name="floating2">
            <pose> -0.285 0 0.05 0 0 3.141592653589793</pose>
            <inertial>
                <pose>0 0 0 0 0 0</pose>
                <mass>5.615E+01</mass>
                <inertia>
                    <ixx>4.649</ixx>
                    <ixy>0</ixy>
                    <ixz>0</ixz>
                    <iyy>4.770e-01</iyy>
                    <iyz>0</iyz>
                    <izz>4.868</izz>
                </inertia>
            </inertial>

            <visual name='floating2'>
                <pose>0 0 0 0 0 0</pose>
                <geometry>
                <mesh>
                    <scale>0.001 0.001 0.001</scale>
                    <uri>model://HG_boat/meshes/Flotation_v1.stl</uri>
                </mesh>
                </geometry>
            </visual>

            <collision name='floating2_collision'>
                <pose>0 0 0 0 0 0</pose>
                <geometry>
                    <mesh>
                        <scale>0.001 0.001 0.001</scale>
                        <uri>model://HG_boat/meshes/Flotation_v1.stl</uri>
                    </mesh>
                </geometry>
            </collision>

        </link>

        <joint name="joint_floating2_body" type="revolute">
            <pose> 0 0 0 0 0 0</pose>
            <parent>base_link</parent>
            <child>floating2</child>
            <axis>
                <xyz>0 0 0</xyz>
                <limit>
                    <lower>0</lower>
                    <upper>0</upper>
                </limit>
                <dynamics>
                <!-- <damping>0.05</damping>
                <friction>0.05</friction> -->
                    <spring_reference>0</spring_reference>
                    <spring_stiffness>0</spring_stiffness>
                </dynamics>
                <use_parent_model_frame>1</use_parent_model_frame>
            </axis>
        </joint>


        <link name="engine1">
            <pose>0.280 0.602169 -0.107824 1.5707963267948966 0 0</pose>
            <inertial>
                <pose>0 0 0 0 0 0</pose>
                <mass>0.198503361</mass>
                <inertia>
                    <ixx>0.00017241962565276868</ixx>
                    <ixy>-0.0000000018044892613665173</ixy>
                    <ixz>0.000000003248300150199609</ixz>
                    <iyy>0.00016751791146215215</iyy>
                    <iyz>0.000000713309154604644</iyz>
                    <izz>0.00019017919460459197</izz>
                </inertia>
            </inertial>

            <visual name='engine1'>
                <pose>0 0 0 0 0 0</pose>
                <geometry>
                <mesh>
                    <scale>0.001 0.001 0.001</scale>
                    <uri>model://HG_boat/meshes/T200-THRUSTER-body-R1_v1.stl</uri>
                </mesh>
                </geometry>
            </visual>

            <collision name='engine1_collision'>
                <pose>0 0 0 0 0 0</pose>
                <geometry>
                    <mesh>
                        <scale>0.001 0.001 0.001</scale>
                        <uri>model://HG_boat/meshes/T200-THRUSTER-body-R1_v1.stl</uri>
                    </mesh>
                </geometry>
            </collision>

        </link>

        <!-- <gazebo reference="engine1">
            <material>Gazebo/Black</material>
            <turnGravityOff>false</turnGravityOff>
        </gazebo> -->

        <joint name="joint_floating1_engine1" type="revolute">
            <pose> 0 0 0 0 0 0</pose>
            <parent>floating1</parent>
            <child>engine1</child>
            <axis>
                <xyz>0 0 0</xyz>
                <limit>
                    <lower>0</lower>
                    <upper>0</upper>
                </limit>
                <dynamics>
                <!-- <damping>0.05</damping>
                <friction>0.05</friction> -->
                    <spring_reference>0</spring_reference>
                    <spring_stiffness>0</spring_stiffness>
                </dynamics>
                <use_parent_model_frame>1</use_parent_model_frame>
            </axis>
        </joint>

       <link name="engine2">

            <pose>-0.280 0.602169 -0.107824 1.5707963267948966 0 0</pose>
            <inertial>
                <pose>0 0 0 0 0 0</pose>
                <mass>0.198503361</mass>
                <inertia>
                    <ixx>0.00017241962565276868</ixx>
                    <ixy>-0.0000000018044892613665173</ixy>
                    <ixz>0.000000003248300150199609</ixz>
                    <iyy>0.00016751791146215215</iyy>
                    <iyz>0.000000713309154604644</iyz>
                    <izz>0.00019017919460459197</izz>
                </inertia>
            </inertial>

            <visual name='engine2'>
                <pose>0 0 0 0 0 0</pose>
                <geometry>
                <mesh>
                    <scale>0.001 0.001 0.001</scale>
                    <uri>model://HG_boat/meshes/T200-THRUSTER-body-R1_v1.stl</uri>
                </mesh>
                </geometry>
            </visual>

             <collision name='engine2_collision'>
                <pose>0 0 0 0 0 0</pose>
                <geometry>
                    <mesh>
                        <scale>0.001 0.001 0.001</scale>
                        <uri>model://HG_boat/meshes/T200-THRUSTER-body-R1_v1.stl</uri>
                    </mesh>
                </geometry>
            </collision>

        </link>

        <!-- <gazebo reference="engine2">
            <material>Gazebo/Black</material>
            <turnGravityOff>false</turnGravityOff>
        </gazebo> -->

        <joint name="joint_floating2_engine2" type="revolute">
            <pose>0 0 0 0 0 0</pose>
            <parent>floating2</parent>
            <child>engine2</child>
            <axis>
                <xyz>0 0 0</xyz>
                <limit>
                    <lower>0</lower>
                    <upper>0</upper>
                </limit>
                <dynamics>
                    <spring_reference>0</spring_reference>
                    <spring_stiffness>0</spring_stiffness>
                </dynamics>
                <use_parent_model_frame>1</use_parent_model_frame>
            </axis>
        </joint>

        <link name="propeller1">
            <pose>0.280 0.602169 -0.107824 1.5707963267948966 0 0</pose>
            <inertial>
                <pose>0 0 0 0 0 0</pose>
                <mass>0.2</mass>
                <inertia>
                   <ixx>0.00011257254904800001</ixx>
                    <ixy>0</ixy>
                    <ixz>0</ixz>
                    <iyy>9.8542738398e-05</iyy>
                    <iyz>0</iyz>
                    <izz>0.000181069670118</izz>
                </inertia>
            </inertial>

            <visual name='propeller1'>
                <pose>0 0 0 0 0 0</pose>
                <geometry>
                <mesh>
                    <scale>0.001 0.001 0.001</scale>
                    <uri>model://HG_boat/meshes/T200-THRUSTER-propeller-R1_v1.stl</uri>
                </mesh>
                </geometry>
            </visual>

            <collision name='propeller1_collision'>
                <pose>0 0 0 0 0 0</pose>
                <geometry>
                    <mesh>
                        <scale>0.001 0.001 0.001</scale>
                        <uri>model://HG_boat/meshes/T200-THRUSTER-propeller-R1_v1.stl</uri>
                    </mesh>
                </geometry>
            </collision>

        </link>


        <joint name='engine1_propeller1_joint' type='revolute'>
            <child>propeller1</child>
            <parent>engine1</parent>
            <axis>
                <xyz>0 -1 0</xyz>
                <limit>
                <lower>-1e+19</lower>
                <upper>1e+19</upper>
                </limit>
                <dynamics>
                <!-- <damping>0.05</damping>
                <friction>0.05</friction> -->
                <spring_reference>0</spring_reference>
                <spring_stiffness>0</spring_stiffness>
                </dynamics>
                <use_parent_model_frame>1</use_parent_model_frame>
            </axis>
        </joint>

        <link name="propeller2">
            <pose>-0.280 0.602169 -0.107824 1.5707963267948966 0 0</pose>
            <inertial>
                <pose>0 0 0 0 0 0</pose>
                <mass>0.2</mass>
                <inertia>
                    <ixx>0.00011257254904800001</ixx>
                    <ixy>0</ixy>
                    <ixz>0</ixz>
                    <iyy>9.8542738398e-05</iyy>
                    <iyz>0</iyz>
                    <izz>0.000181069670118</izz>
                </inertia>
            </inertial>

            <visual name='propeller2'>
                <pose>0 0 0 0 0 0</pose>
                <geometry>
                <mesh>
                    <scale>0.001 0.001 0.001</scale>
                    <uri>model://HG_boat/meshes/T200-THRUSTER-propeller-R1_v1.stl</uri>
                </mesh>
                </geometry>
            </visual>

            <collision name='propeller2_collision'>
                <pose>0 0 0 0.7853981633974483 0 0</pose>
                <geometry>
                    <mesh>
                        <scale>0.001 0.001 0.001</scale>
                        <uri>model://HG_boat/meshes/T200-THRUSTER-propeller-R1_v1.stl</uri>
                    </mesh>
                </geometry>
            </collision>

        </link>


        <joint name='engine2_propeller2_joint' type='revolute'>
            <child>propeller2</child>
            <parent>engine2</parent>
            <axis>
                <xyz>0 -1 0</xyz>
                <limit>
                <lower>-1e+19</lower>
                <upper>1e+19</upper>
                </limit>
                <dynamics>
                <!-- <damping>0.05</damping>
                <friction>0.05</friction> -->
                <spring_reference>0</spring_reference>
                <spring_stiffness>0</spring_stiffness>
                </dynamics>
                <use_parent_model_frame>1</use_parent_model_frame>
            </axis>
        </joint>

        <link name='imu_link'>
            <!-- <pose>0 0 0 0 0 3.1415927</pose> -->
            <pose>0 0 0.2 3.141592653589793 0 0</pose>
            <inertial>
                <pose>0 0 0 0 0 0</pose>
                <mass>0.015</mass>
                <inertia>
                <ixx>1e-05</ixx>
                <ixy>0</ixy>
                <ixz>0</ixz>
                <iyy>1e-05</iyy>
                <iyz>0</iyz>
                <izz>1e-05</izz>
                </inertia>
            </inertial>
            <sensor name="imu_sensor" type="imu">
                <pose>0 0 0 0 0 0</pose>
                <always_on>1</always_on>
                <update_rate>1000.0</update_rate>
            </sensor>
        </link>
        <joint name='imu_joint' type='revolute'>
            <child>imu_link</child>
            <parent>base_link</parent>
            <axis>
                <xyz>1 0 0</xyz>
                <limit>
                <lower>0</lower>
                <upper>0</upper>
                <effort>0</effort>
                <velocity>0</velocity>
                </limit>
                <dynamics>
                <damping>0.7</damping>
                </dynamics>
                <use_parent_model_frame>1</use_parent_model_frame>
            </axis>
        </joint>
        

        <plugin name='usv_dynamics_wamv_dynamics_plugin' filename='libusv_gazebo_dynamics_plugin.so'>
            <bodyName>floating1</bodyName>
            <waterLevel>0</waterLevel>
            <waterDensity>997.8</waterDensity>
            <xDotU>0.0</xDotU>
            <yDotV>0.0</yDotV>
            <nDotR>0.0</nDotR>
            <xU>51.3</xU>
            <xUU>72.4</xUU>
            <yV>40.0</yV>
            <yVV>0.0</yVV>
            <zW>500.0</zW>
            <kP>50.0</kP>
            <mQ>50.0</mQ>
            <nR>500.0</nR>
            <nRR>0.0</nRR>
            <hullRadius>1.4</hullRadius>
            <boatWidth>1.4</boatWidth>
            <boatLength>1.0</boatLength>
            <length_n>1</length_n>
            <wave_model>ocean_wave</wave_model>
        </plugin>

        <plugin name='usv_dynamics_wamv_dynamics_plugin1' filename='libusv_gazebo_dynamics_plugin.so'>
            <bodyName>floating2</bodyName>
            <waterLevel>0</waterLevel>
            <waterDensity>997.8</waterDensity>
            <xDotU>0.0</xDotU>
            <yDotV>0.0</yDotV>
            <nDotR>0.0</nDotR>
            <xU>51.3</xU>
            <xUU>72.4</xUU>
            <yV>40.0</yV>
            <yVV>0.0</yVV>
            <zW>500.0</zW>
            <kP>50.0</kP>
            <mQ>50.0</mQ>
            <nR>500.0</nR>
            <nRR>0.0</nRR>
            <hullRadius>1.4</hullRadius>
            <boatWidth>1.4</boatWidth>
            <boatLength>1.0</boatLength>
            <length_n>1</length_n>
            <wave_model>ocean_wave</wave_model>
        </plugin>

        <plugin name="ArduCopter_Plugin" filename="libArduPilotPlugin.so">
            <fdm_addr>127.0.0.1</fdm_addr>
            <fdm_port_in>9002</fdm_port_in>
            <fdm_port_out>9003</fdm_port_out>
            <!--
                Require by APM :
                Only change model and gazebo from XYZ to XY-Z coordinates
            -->
            <!-- 3.141593 -->
            <modelXYZToAirplaneXForwardZDown>0 0 0 3.141593 0 -1.5707963267948966</modelXYZToAirplaneXForwardZDown>
            <gazeboXYZToNED>0 0 0 3.141593 0 -1.5707963267948966</gazeboXYZToNED>
            <imuName>HG_boat::imu_link::imu_sensor</imuName>
            <connectionTimeoutMaxCount>5</connectionTimeoutMaxCount>
            <!--
                incoming control command [0, 1]
                so offset it by 0 to get [0, 1]
                and divide max target by 1.
                offset = 0
                multiplier = 838 max rpm / 1 = 838
                -->
            <control channel="0">
                <type>VELOCITY</type>
                <offset>-0.5</offset>
                <p_gain>0.5</p_gain>
                <i_gain>0</i_gain>
                <d_gain>0</d_gain>
                <i_max>0</i_max>
                <i_min>0</i_min>
                <cmd_max>10</cmd_max>
                <cmd_min>-10</cmd_min>
                <jointName>engine1_propeller1_joint</jointName>
                <multiplier>300</multiplier>
            </control>
            <control channel="2">
                <type>VELOCITY</type>
                <offset>-0.5</offset>
                <p_gain>0.5</p_gain>
                <i_gain>0</i_gain>
                <d_gain>0</d_gain>
                <i_max>0</i_max>
                <i_min>0</i_min>
                <cmd_max>10</cmd_max>
                <cmd_min>-10</cmd_min>
                <jointName>engine2_propeller2_joint</jointName>
                <multiplier>300</multiplier>
            </control>
            
        </plugin>

        <plugin name='prop1_blade_1' filename='libLiftDragPlugin.so'>
            <a0>0.08727</a0>
            <cla>5.418</cla>
            <cda>0.0</cda>
            <alpha_stall>0.3368</alpha_stall>
            <cla_stall>0.0</cla_stall>
            <cda_stall>0.0</cda_stall>
            <area>0.002</area>
            <air_density>997</air_density>

            <cp>-0.015 0.024 0.005</cp>
            <forward>0.04 0.021 -0.023</forward>
            <upward>-0.019 -0.017 -0.034</upward>
            <link_name>propeller1</link_name>
        </plugin>

        <plugin name='prop1_blade_2' filename='libLiftDragPlugin.so'>
            <a0>0.4</a0>
            <cla>4.752798721</cla>
            <cda>0.6417112299</cda>
            <alpha_stall>1.5</alpha_stall>
            <cla_stall>-3.85</cla_stall>
            <cda_stall>-0.9233984055</cda_stall>
            <area>0.002</area>
            <air_density>997</air_density>

            <cp>-0.013 -0.025 0.005</cp>
            <forward>-0.038 0.023 -0.023</forward>
            <upward>0.024 -0.008 -0.034</upward>
            <link_name>propeller1</link_name>
        </plugin>

        <plugin name='prop1_blade_3' filename='libLiftDragPlugin.so'>
            <a0>0.4</a0>
            <cla>4.752798721</cla>
            <cda>0.6417112299</cda>
            <alpha_stall>1.5</alpha_stall>
            <cla_stall>-3.85</cla_stall>
            <cda_stall>-0.9233984055</cda_stall>
            <area>0.002</area>
            <air_density>997</air_density>

            <cp>0.028 0.001 0.005</cp>
            <forward>-0.001 -0.045 -0.023</forward>
            <upward>-0.005 0.025 -0.034</upward>
            <link_name>propeller1</link_name>
        </plugin>


        <plugin name='prop2_blade_1' filename='libLiftDragPlugin.so'>
            <a0>0.08727</a0>
            <cla>5.418</cla>
            <cda>0.0</cda>
            <alpha_stall>0.3368</alpha_stall>
            <cla_stall>0.0</cla_stall>
            <cda_stall>0.0</cda_stall>
            <area>0.002</area>
            <air_density>997</air_density>

            <cp>-0.015 0.024 0.005</cp>
            <forward>0.04 0.021 -0.023</forward>
            <upward>-0.019 -0.017 -0.034</upward>
            <link_name>propeller2</link_name>
        </plugin>

        <plugin name='prop2_blade_2' filename='libLiftDragPlugin.so'>
            <a0>0.4</a0>
            <cla>4.752798721</cla>
            <cda>0.6417112299</cda>
            <alpha_stall>1.5</alpha_stall>
            <cla_stall>-3.85</cla_stall>
            <cda_stall>-0.9233984055</cda_stall>
            <area>0.002</area>
            <air_density>997</air_density>

            <cp>-0.013 -0.025 0.005</cp>
            <forward>-0.038 0.023 -0.023</forward>
            <upward>0.024 -0.008 -0.034</upward>
            <link_name>propeller2</link_name>
        </plugin>

        <plugin name='prop2_blade_3' filename='libLiftDragPlugin.so'>
            <a0>0.4</a0>
            <cla>4.752798721</cla>
            <cda>0.6417112299</cda>
            <alpha_stall>1.5</alpha_stall>
            <cla_stall>-3.85</cla_stall>
            <cda_stall>-0.9233984055</cda_stall>
            <area>0.002</area>
            <air_density>997</air_density>

            <cp>0.028 0.001 0.005</cp>
            <forward>-0.001 -0.045 -0.023</forward>
            <upward>-0.005 0.025 -0.034</upward>
            <link_name>propeller2</link_name>
        </plugin>
    
    </model>
</sdf>